Workbook

Sheet Raw_Data
A1: user_id | B1: signup_date | C1: experiment_group | D1: region | E1: device_type | F1: traffic_source | G1: plan_type | H1: visited_landing_page | I1: started_trial | J1: completed_onboarding | K1: converted_to_paid | L1: revenue_30d | M1: support_tickets_30d | N1: refund_requested | O1: days_to_convert | P1: engagement_score | Q1: has_support_ticket | R1: ctrl_days_to_convert | S1: trt_days_to_convert | T1: ctrl_engagement | U1: trt_engagement
A2: USR-100001 | B2: 45732 | C2: Control | D2: North | E2: Desktop | F2: Email | G2: Basic | H2: 0 | I2: 0 | J2: 0 | K2: 0 | L2: 0 | M2: 0 | N2: 0 | P2: 45.7 | Q2: =IF(M2>0,1,0) -> 0 | R2: =IF(AND(C2="Control",K2=1),O2,"") | S2: =IF(AND(C2="Treatment",K2=1),O2,"") | T2: =IF(AND(C2="Control",P2<>""),P2,"") -> 45.7 | U2: =IF(AND(C2="Treatment",P2<>""),P2,"")
A3: USR-100002 | B3: 45724 | C3: Control | D3: West | E3: Mobile | F3: Organic | G3: Free | H3: 1 | I3: 0 | J3: 0 | K3: 0 | L3: 0 | M3: 0 | N3: 0 | P3: 48.6 | Q3: =IF(M3>0,1,0) -> 0 | R3: =IF(AND(C3="Control",K3=1),O3,"") | S3: =IF(AND(C3="Treatment",K3=1),O3,"") | T3: =IF(AND(C3="Control",P3<>""),P3,"") -> 48.6 | U3: =IF(AND(C3="Treatment",P3<>""),P3,"")
A4: USR-100003 | B4: 45771 | C4: Control | D4: East | E4: Mobile | F4: Paid Search | G4: Premium | H4: 1 | I4: 0 | J4: 0 | K4: 0 | L4: 0 | M4: 1 | N4: 0 | P4: 35.4 | Q4: =IF(M4>0,1,0) -> 1 | R4: =IF(AND(C4="Control",K4=1),O4,"") | S4: =IF(AND(C4="Treatment",K4=1),O4,"") | T4: =IF(AND(C4="Control",P4<>""),P4,"") -> 35.4 | U4: =IF(AND(C4="Treatment",P4<>""),P4,"")
A5: USR-100004 | B5: 45781 | C5: Control | D5: South | E5: Mobile | F5: Email | G5: Basic | H5: 1 | I5: 0 | J5: 0 | K5: 0 | L5: 0 | M5: 0 | N5: 0 | P5: 64.6 | Q5: =IF(M5>0,1,0) -> 0 | R5: =IF(AND(C5="Control",K5=1),O5,"") | S5: =IF(AND(C5="Treatment",K5=1),O5,"") | T5: =IF(AND(C5="Control",P5<>""),P5,"") -> 64.6 | U5: =IF(AND(C5="Treatment",P5<>""),P5,"")
A6: USR-100005 | B6: 45700 | C6: Control | D6: North | E6: Tablet | F6: Organic | G6: Free | H6: 0 | I6: 0 | J6: 0 | K6: 0 | L6: 0 | M6: 0 | N6: 0 | P6: 66.6 | Q6: =IF(M6>0,1,0) -> 0 | R6: =IF(AND(C6="Control",K6=1),O6,"") | S6: =IF(AND(C6="Treatment",K6=1),O6,"") | T6: =IF(AND(C6="Control",P6<>""),P6,"") -> 66.6 | U6: =IF(AND(C6="Treatment",P6<>""),P6,"")
A7: USR-100006 | B7: 45685 | C7: Control | D7: East | E7: Mobile | F7: Organic | G7: Premium | H7: 1 | I7: 0 | J7: 0 | K7: 0 | L7: 0 | M7: 0 | N7: 0 | P7: 40.8 | Q7: =IF(M7>0,1,0) -> 0 | R7: =IF(AND(C7="Control",K7=1),O7,"") | S7: =IF(AND(C7="Treatment",K7=1),O7,"") | T7: =IF(AND(C7="Control",P7<>""),P7,"") -> 40.8 | U7: =IF(AND(C7="Treatment",P7<>""),P7,"")
A8: USR-100007 | B8: 45755 | C8: Control | D8: East | E8: Mobile | F8: Paid Search | G8: Basic | H8: 1 | I8: 1 | J8: 0 | K8: 0 | L8: 0 | M8: 0 | N8: 0 | P8: 57.1 | Q8: =IF(M8>0,1,0) -> 0 | R8: =IF(AND(C8="Control",K8=1),O8,"") | S8: =IF(AND(C8="Treatment",K8=1),O8,"") | T8: =IF(AND(C8="Control",P8<>""),P8,"") -> 57.1 | U8: =IF(AND(C8="Treatment",P8<>""),P8,"")
A9: USR-100008 | B9: 45794 | C9: Control | D9: South | E9: Mobile | F9: Paid Search | G9: Free | H9: 0 | I9: 0 | J9: 0 | K9: 0 | L9: 0 | M9: 0 | N9: 0 | P9: 36.4 | Q9: =IF(M9>0,1,0) -> 0 | R9: =IF(AND(C9="Control",K9=1),O9,"") | S9: =IF(AND(C9="Treatment",K9=1),O9,"") | T9: =IF(AND(C9="Control",P9<>""),P9,"") -> 36.4 | U9: =IF(AND(C9="Treatment",P9<>""),P9,"")
A10: USR-100009 | B10: 45711 | C10: Control | D10: South | E10: Tablet | F10: Referral | G10: Basic | H10: 0 | I10: 0 | J10: 0 | K10: 0 | L10: 0 | M10: 0 | N10: 0 | P10: 55.4 | Q10: =IF(M10>0,1,0) -> 0 | R10: =IF(AND(C10="Control",K10=1),O10,"") | S10: =IF(AND(C10="Treatment",K10=1),O10,"") | T10: =IF(AND(C10="Control",P10<>""),P10,"") -> 55.4 | U10: =IF(AND(C10="Treatment",P10<>""),P10,"")
A11: USR-100010 | B11: 45806 | C11: Control | D11: West | E11: Desktop | F11: Social | G11: Free | H11: 1 | I11: 0 | J11: 0 | K11: 0 | L11: 0 | M11: 0 | N11: 0 | P11: 57.3 | Q11: =IF(M11>0,1,0) -> 0 | R11: =IF(AND(C11="Control",K11=1),O11,"") | S11: =IF(AND(C11="Treatment",K11=1),O11,"") | T11: =IF(AND(C11="Control",P11<>""),P11,"") -> 57.3 | U11: =IF(AND(C11="Treatment",P11<>""),P11,"")
A12: USR-100011 | B12: 45777 | C12: Control | D12: East | E12: Mobile | F12: Paid Search | G12: Basic | H12: 1 | I12: 1 | J12: 1 | K12: 0 | L12: 0 | M12: 0 | N12: 0 | P12: 63.6 | Q12: =IF(M12>0,1,0) -> 0 | R12: =IF(AND(C12="Control",K12=1),O12,"") | S12: =IF(AND(C12="Treatment",K12=1),O12,"") | T12: =IF(AND(C12="Control",P12<>""),P12,"") -> 63.6 | U12: =IF(AND(C12="Treatment",P12<>""),P12,"")
A13: USR-100012 | B13: 45732 | C13: Control | D13: East | E13: Mobile | F13: Social | G13: Premium | H13: 1 | I13: 1 | J13: 1 | K13: 0 | L13: 0 | M13: 1 | N13: 0 | P13: 80.4 | Q13: =IF(M13>0,1,0) -> 1 | R13: =IF(AND(C13="Control",K13=1),O13,"") | S13: =IF(AND(C13="Treatment",K13=1),O13,"") | T13: =IF(AND(C13="Control",P13<>""),P13,"") -> 80.4 | U13: =IF(AND(C13="Treatment",P13<>""),P13,"")
... A60: USR-100059 | B60: 45761 | C60: Control | D60: North | E60: Mobile | F60: Social | G60: Free | H60: 0 | I60: 0 | J60: 0 | K60: 0 | L60: 0 | M60: 2 | N60: 0 | P60: 48.9 | Q60: =IF(M60>0,1,0) -> 1 | R60: =IF(AND(C60="Control",K60=1),O60,"") | S60: =IF(AND(C60="Treatment",K60=1),O60,"") | T60: =IF(AND(C60="Control",P60<>""),P60,"") -> 48.9 | U60: =IF(AND(C60="Treatment",P60<>""),P60,"")
A61: USR-100060 | B61: 45658 | C61: Control | D61: West | E61: Mobile | F61: Social | G61: Free | H61: 1 | I61: 1 | J61: 1 | K61: 1 | L61: 240.42 | M61: 0 | N61: 0 | O61: 16 | P61: 56.5 | Q61: =IF(M61>0,1,0) -> 0 | R61: =IF(AND(C61="Control",K61=1),O61,"") -> 16 | S61: =IF(AND(C61="Treatment",K61=1),O61,"") | T61: =IF(AND(C61="Control",P61<>""),P61,"") -> 56.5 | U61: =IF(AND(C61="Treatment",P61<>""),P61,"")
A62: USR-100061 | B62: 45749 | C62: Control | D62: South | E62: Mobile | F62: Referral | G62: Free | H62: 1 | I62: 0 | J62: 0 | K62: 0 | L62: 0 | M62: 0 | N62: 0 | P62: 53.7 | Q62: =IF(M62>0,1,0) -> 0 | R62: =IF(AND(C62="Control",K62=1),O62,"") | S62: =IF(AND(C62="Treatment",K62=1),O62,"") | T62: =IF(AND(C62="Control",P62<>""),P62,"") -> 53.7 | U62: =IF(AND(C62="Treatment",P62<>""),P62,"")
A63: USR-100062 | B63: 45745 | C63: Control | D63: North | E63: Mobile | F63: Social | G63: Premium | H63: 0 | I63: 0 | J63: 0 | K63: 0 | L63: 0 | M63: 0 | N63: 0 | P63: 62.2 | Q63: =IF(M63>0,1,0) -> 0 | R63: =IF(AND(C63="Control",K63=1),O63,"") | S63: =IF(AND(C63="Treatment",K63=1),O63,"") | T63: =IF(AND(C63="Control",P63<>""),P63,"") -> 62.2 | U63: =IF(AND(C63="Treatment",P63<>""),P63,"")
A64: USR-100063 | B64: 45792 | C64: Control | D64: South | E64: Desktop | F64: Organic | G64: Free | H64: 1 | I64: 0 | J64: 0 | K64: 0 | L64: 0 | M64: 0 | N64: 0 | P64: 50.2 | Q64: =IF(M64>0,1,0) -> 0 | R64: =IF(AND(C64="Control",K64=1),O64,"") | S64: =IF(AND(C64="Treatment",K64=1),O64,"") | T64: =IF(AND(C64="Control",P64<>""),P64,"") -> 50.2 | U64: =IF(AND(C64="Treatment",P64<>""),P64,"")
A65: USR-100064 | B65: 45758 | C65: Control | D65: North | E65: Mobile | F65: Organic | G65: Basic | H65: 1 | I65: 0 | J65: 0 | K65: 0 | L65: 0 | M65: 0 | N65: 0 | P65: 74.3 | Q65: =IF(M65>0,1,0) -> 0 | R65: =IF(AND(C65="Control",K65=1),O65,"") | S65: =IF(AND(C65="Treatment",K65=1),O65,"") | T65: =IF(AND(C65="Control",P65<>""),P65,"") -> 74.3 | U65: =IF(AND(C65="Treatment",P65<>""),P65,"")
A66: USR-100065 | B66: 45723 | C66: Control | D66: South | E66: Desktop | F66: Paid Search | G66: Free | H66: 1 | I66: 0 | J66: 0 | K66: 0 | L66: 0 | M66: 0 | N66: 0 | P66: 58 | Q66: =IF(M66>0,1,0) -> 0 | R66: =IF(AND(C66="Control",K66=1),O66,"") | S66: =IF(AND(C66="Treatment",K66=1),O66,"") | T66: =IF(AND(C66="Control",P66<>""),P66,"") -> 58 | U66: =IF(AND(C66="Treatment",P66<>""),P66,"")
A67: USR-100066 | B67: 45807 | C67: Control | D67: South | E67: Mobile | F67: Organic | G67: Free | H67: 0 | I67: 0 | J67: 0 | K67: 0 | L67: 0 | M67: 0 | N67: 0 | P67: 46.7 | Q67: =IF(M67>0,1,0) -> 0 | R67: =IF(AND(C67="Control",K67=1),O67,"") | S67: =IF(AND(C67="Treatment",K67=1),O67,"") | T67: =IF(AND(C67="Control",P67<>""),P67,"") -> 46.7 | U67: =IF(AND(C67="Treatment",P67<>""),P67,"")
A68: USR-100067 | B68: 45664 | C68: Control | D68: South | E68: Desktop | F68: Organic | G68: Premium | H68: 1 | I68: 0 | J68: 0 | K68: 0 | L68: 0 | M68: 1 | N68: 0 | P68: 49.6 | Q68: =IF(M68>0,1,0) -> 1 | R68: =IF(AND(C68="Control",K68=1),O68,"") | S68: =IF(AND(C68="Treatment",K68=1),O68,"") | T68: =IF(AND(C68="Control",P68<>""),P68,"") -> 49.6 | U68: =IF(AND(C68="Treatment",P68<>""),P68,"")
A69: USR-100068 | B69: 45785 | C69: Control | D69: West | E69: Mobile | F69: Social | G69: Free | H69: 0 | I69: 0 | J69: 0 | K69: 0 | L69: 0 | M69: 0 | N69: 0 | P69: 60.4 | Q69: =IF(M69>0,1,0) -> 0 | R69: =IF(AND(C69="Control",K69=1),O69,"") | S69: =IF(AND(C69="Treatment",K69=1),O69,"") | T69: =IF(AND(C69="Control",P69<>""),P69,"") -> 60.4 | U69: =IF(AND(C69="Treatment",P69<>""),P69,"")
A70: USR-100069 | B70: 45735 | C70: Control | D70: East | E70: Desktop | F70: Email | G70: Free | H70: 1 | I70: 1 | J70: 1 | K70: 0 | L70: 0 | M70: 0 | N70: 0 | P70: 55.3 | Q70: =IF(M70>0,1,0) -> 0 | R70: =IF(AND(C70="Control",K70=1),O70,"") | S70: =IF(AND(C70="Treatment",K70=1),O70,"") | T70: =IF(AND(C70="Control",P70<>""),P70,"") -> 55.3 | U70: =IF(AND(C70="Treatment",P70<>""),P70,"")
A71: USR-100070 | B71: 45793 | C71: Control | D71: North | E71: Desktop | F71: Organic | G71: Free | H71: 0 | I71: 0 | J71: 0 | K71: 0 | L71: 0 | M71: 0 | N71: 0 | P71: 56.2 | Q71: =IF(M71>0,1,0) -> 0 | R71: =IF(AND(C71="Control",K71=1),O71,"") | S71: =IF(AND(C71="Treatment",K71=1),O71,"") | T71: =IF(AND(C71="Control",P71<>""),P71,"") -> 56.2 | U71: =IF(AND(C71="Treatment",P71<>""),P71,"")
A72: USR-100071 | B72: 45724 | C72: Control | D72: West | E72: Mobile | F72: Email | G72: Free | H72: 0 | I72: 0 | J72: 0 | K72: 0 | L72: 0 | M72: 0 | N72: 0 | P72: 29.4 | Q72: =IF(M72>0,1,0) -> 0 | R72: =IF(AND(C72="Control",K72=1),O72,"") | S72: =IF(AND(C72="Treatment",K72=1),O72,"") | T72: =IF(AND(C72="Control",P72<>""),P72,"") -> 29.4 | U72: =IF(AND(C72="Treatment",P72<>""),P72,"")
A73: USR-100072 | B73: 45724 | C73: Control | D73: East | E73: Mobile | F73: Email | G73: Free | H73: 1 | I73: 0 | J73: 0 | K73: 0 | L73: 0 | M73: 0 | N73: 0 | P73: 54.2 | Q73: =IF(M73>0,1,0) -> 0 | R73: =IF(AND(C73="Control",K73=1),O73,"") | S73: =IF(AND(C73="Treatment",K73=1),O73,"") | T73: =IF(AND(C73="Control",P73<>""),P73,"") -> 54.2 | U73: =IF(AND(C73="Treatment",P73<>""),P73,"")
... A79: USR-100078 | B79: 45673 | C79: Control | D79: North | E79: Mobile | F79: Organic | G79: Free | H79: 0 | I79: 0 | J79: 0 | K79: 0 | L79: 0 | M79: 2 | N79: 0 | P79: 48.4 | Q79: =IF(M79>0,1,0) -> 1 | R79: =IF(AND(C79="Control",K79=1),O79,"") | S79: =IF(AND(C79="Treatment",K79=1),O79,"") | T79: =IF(AND(C79="Control",P79<>""),P79,"") -> 48.4 | U79: =IF(AND(C79="Treatment",P79<>""),P79,"")
A80: USR-100079 | B80: 45708 | C80: Control | D80: West | E80: Desktop | F80: Organic | G80: Free | H80: 1 | I80: 1 | J80: 1 | K80: 1 | L80: 457.51 | M80: 0 | N80: 0 | O80: 7 | P80: 38 | Q80: =IF(M80>0,1,0) -> 0 | R80: =IF(AND(C80="Control",K80=1),O80,"") -> 7 | S80: =IF(AND(C80="Treatment",K80=1),O80,"") | T80: =IF(AND(C80="Control",P80<>""),P80,"") -> 38 | U80: =IF(AND(C80="Treatment",P80<>""),P80,"")
A81: USR-100080 | B81: 45798 | C81: Control | D81: East | E81: Mobile | F81: Social | G81: Free | H81: 1 | I81: 0 | J81: 0 | K81: 0 | L81: 0 | M81: 0 | N81: 0 | P81: 44.2 | Q81: =IF(M81>0,1,0) -> 0 | R81: =IF(AND(C81="Control",K81=1),O81,"") | S81: =IF(AND(C81="Treatment",K81=1),O81,"") | T81: =IF(AND(C81="Control",P81<>""),P81,"") -> 44.2 | U81: =IF(AND(C81="Treatment",P81<>""),P81,"")
A82: USR-100081 | B82: 45785 | C82: Control | D82: South | E82: Mobile | F82: Organic | G82: Free | H82: 1 | I82: 1 | J82: 1 | K82: 0 | L82: 0 | M82: 0 | N82: 0 | P82: 81.2 | Q82: =IF(M82>0,1,0) -> 0 | R82: =IF(AND(C82="Control",K82=1),O82,"") | S82: =IF(AND(C82="Treatment",K82=1),O82,"") | T82: =IF(AND(C82="Control",P82<>""),P82,"") -> 81.2 | U82: =IF(AND(C82="Treatment",P82<>""),P82,"")
A83: USR-100082 | B83: 45724 | C83: Control | D83: South | E83: Mobile | F83: Referral | G83: Free | H83: 1 | I83: 1 | J83: 0 | K83: 0 | L83: 0 | M83: 0 | N83: 0 | P83: 63.8 | Q83: =IF(M83>0,1,0) -> 0 | R83: =IF(AND(C83="Control",K83=1),O83,"") | S83: =IF(AND(C83="Treatment",K83=1),O83,"") | T83: =IF(AND(C83="Control",P83<>""),P83,"") -> 63.8 | U83: =IF(AND(C83="Treatment",P83<>""),P83,"")
A84: USR-100083 | B84: 45748 | C84: Control | D84: South | E84: Desktop | F84: Email | G84: Free | H84: 0 | I84: 0 | J84: 0 | K84: 0 | L84: 0 | M84: 0 | N84: 0 | P84: 64.7 | Q84: =IF(M84>0,1,0) -> 0 | R84: =IF(AND(C84="Control",K84=1),O84,"") | S84: =IF(AND(C84="Treatment",K84=1),O84,"") | T84: =IF(AND(C84="Control",P84<>""),P84,"") -> 64.7 | U84: =IF(AND(C84="Treatment",P84<>""),P84,"")
A85: USR-100084 | B85: 45719 | C85: Control | D85: West | E85: Mobile | F85: Social | G85: Basic | H85: 0 | I85: 0 | J85: 0 | K85: 0 | L85: 0 | M85: 0 | N85: 0 | P85: 60.4 | Q85: =IF(M85>0,1,0) -> 0 | R85: =IF(AND(C85="Control",K85=1),O85,"") | S85: =IF(AND(C85="Treatment",K85=1),O85,"") | T85: =IF(AND(C85="Control",P85<>""),P85,"") -> 60.4 | U85: =IF(AND(C85="Treatment",P85<>""),P85,"")
A86: USR-100085 | B86: 45763 | C86: Control | D86: South | E86: Mobile | F86: Paid Search | G86: Free | H86: 0 | I86: 0 | J86: 0 | K86: 0 | L86: 0 | M86: 0 | N86: 0 | P86: 66.6 | Q86: =IF(M86>0,1,0) -> 0 | R86: =IF(AND(C86="Control",K86=1),O86,"") | S86: =IF(AND(C86="Treatment",K86=1),O86,"") | T86: =IF(AND(C86="Control",P86<>""),P86,"") -> 66.6 | U86: =IF(AND(C86="Treatment",P86<>""),P86,"")
A87: USR-100086 | B87: 45666 | C87: Control | D87: North | E87: Desktop | F87: Organic | G87: Free | H87: 1 | I87: 0 | J87: 0 | K87: 0 | L87: 0 | M87: 0 | N87: 0 | P87: 50.9 | Q87: =IF(M87>0,1,0) -> 0 | R87: =IF(AND(C87="Control",K87=1),O87,"") | S87: =IF(AND(C87="Treatment",K87=1),O87,"") | T87: =IF(AND(C87="Control",P87<>""),P87,"") -> 50.9 | U87: =IF(AND(C87="Treatment",P87<>""),P87,"")
A88: USR-100087 | B88: 45679 | C88: Control | D88: West | E88: Desktop | F88: Social | G88: Basic | H88: 0 | I88: 0 | J88: 0 | K88: 0 | L88: 0 | M88: 0 | N88: 0 | P88: 51 | Q88: =IF(M88>0,1,0) -> 0 | R88: =IF(AND(C88="Control",K88=1),O88,"") | S88: =IF(AND(C88="Treatment",K88=1),O88,"") | T88: =IF(AND(C88="Control",P88<>""),P88,"") -> 51 | U88: =IF(AND(C88="Treatment",P88<>""),P88,"")
A89: USR-100088 | B89: 45777 | C89: Control | D89: South | E89: Mobile | F89: Email | G89: Premium | H89: 0 | I89: 0 | J89: 0 | K89: 0 | L89: 0 | M89: 0 | N89: 0 | P89: 65.8 | Q89: =IF(M89>0,1,0) -> 0 | R89: =IF(AND(C89="Control",K89=1),O89,"") | S89: =IF(AND(C89="Treatment",K89=1),O89,"") | T89: =IF(AND(C89="Control",P89<>""),P89,"") -> 65.8 | U89: =IF(AND(C89="Treatment",P89<>""),P89,"")
A90: USR-100089 | B90: 45772 | C90: Control | D90: North | E90: Mobile | F90: Referral | G90: Basic | H90: 1 | I90: 0 | J90: 0 | K90: 0 | L90: 0 | M90: 0 | N90: 0 | P90: 61.8 | Q90: =IF(M90>0,1,0) -> 0 | R90: =IF(AND(C90="Control",K90=1),O90,"") | S90: =IF(AND(C90="Treatment",K90=1),O90,"") | T90: =IF(AND(C90="Control",P90<>""),P90,"") -> 61.8 | U90: =IF(AND(C90="Treatment",P90<>""),P90,"")
A91: USR-100090 | B91: 45689 | C91: Control | D91: North | E91: Mobile | F91: Organic | G91: Basic | H91: 1 | I91: 0 | J91: 0 | K91: 0 | L91: 0 | M91: 0 | N91: 0 | P91: 54.5 | Q91: =IF(M91>0,1,0) -> 0 | R91: =IF(AND(C91="Control",K91=1),O91,"") | S91: =IF(AND(C91="Treatment",K91=1),O91,"") | T91: =IF(AND(C91="Control",P91<>""),P91,"") -> 54.5 | U91: =IF(AND(C91="Treatment",P91<>""),P91,"")
...

Sheet Hypothesis_Test
A1: Task 7 — Hypothesis Test: Paid Conversion Rate (North Star)
A3: HYPOTHESIS SETUP
A4: Null hypothesis (H0) | B4: Treatment conversion rate = Control conversion rate
A5: Alternate hypothesis (H1) | B5: Treatment conversion rate > Control conversion rate (one-tailed)
A6: Significance level (alpha) | B6: 0.05
A8: TEST INPUTS (live from Raw_Data)
A9: n1 — Control users | B9: =COUNTIF(Raw_Data!$C$2:$C$1401,"Control") -> 690
A10: n2 — Treatment users | B10: =COUNTIF(Raw_Data!$C$2:$C$1401,"Treatment") -> 710
A11: x1 — Control conversions | B11: =SUMIFS(Raw_Data!$K$2:$K$1401,Raw_Data!$C$2:$C$1401,"Control") -> 22
A12: x2 — Treatment conversions | B12: =SUMIFS(Raw_Data!$K$2:$K$1401,Raw_Data!$C$2:$C$1401,"Treatment") -> 50
A13: p1 — Control conversion rate | B13: =B11/B9 -> 0.031884058
A14: p2 — Treatment conversion rate | B14: =B12/B10 -> 0.070422535
A16: TEST CALCULATION
A17: Pooled proportion | B17: =(B11+B12)/(B9+B10) -> 0.051428571
A18: Standard error (pooled) | B18: =SQRT(B17*(1-B17)*(1/B9+1/B10)) -> 0.011807217
A19: Z-statistic | B19: =(B14-B13)/B18 -> 3.2639763
A20: One-tailed p-value | B20: =1-_xlfn.NORM.S.DIST(B19,TRUE()) -> 0.00054930169
A21: Two-tailed p-value | B21: =2*(1-_xlfn.NORM.S.DIST(ABS(B19),TRUE())) -> 0.0010986034
A23: CONFIDENCE INTERVAL & EFFECT SIZE
A24: Standard error (unpooled) | B24: =SQRT(B13*(1-B13)/B9+B14*(1-B14)/B10) -> 0.011702015
A25: Absolute lift (p2 - p1) | B25: =B14-B13 -> 0.038538477
A26: 95% CI lower bound | B26: =B25-1.96*B24 -> 0.015602528
A27: 95% CI upper bound | B27: =B25+1.96*B24 -> 0.061474426
A28: Relative lift | B28: =B25/B13 -> 1.2087068
A30: DECISION
A31: Decision rule result | B31: =IF(B20<B6,"Reject H0 — statistically significant improvement","Fail to reject H0 — not statistically significant") -> Reject H0 — statistically significant improvement

Sheet Guardrail_Tests
A1: Task 8 — Guardrail Metric Significance Tests
A3: GUARDRAIL 1: SUPPORT TICKET RATE (two-proportion z-test)
A4: Significance level (alpha) | B4: 0.05
A5: n1 — Control users | B5: =COUNTIF(Raw_Data!$C$2:$C$1401,"Control") -> 690
A6: n2 — Treatment users | B6: =COUNTIF(Raw_Data!$C$2:$C$1401,"Treatment") -> 710
A7: x1 — Control users w/ a ticket | B7: =SUMIFS(Raw_Data!$Q$2:$Q$1401,Raw_Data!$C$2:$C$1401,"Control") -> 102
A8: x2 — Treatment users w/ a ticket | B8: =SUMIFS(Raw_Data!$Q$2:$Q$1401,Raw_Data!$C$2:$C$1401,"Treatment") -> 176
A9: p1 — Control ticket rate | B9: =B7/B5 -> 0.14782609
A10: p2 — Treatment ticket rate | B10: =B8/B6 -> 0.24788732
A11: Pooled proportion | B11: =(B7+B8)/(B5+B6) -> 0.19857143
A12: Standard error | B12: =SQRT(B11*(1-B11)*(1/B5+1/B6)) -> 0.021325592
A13: Z-statistic | B13: =(B10-B9)/B12 -> 4.6920732
A14: Two-tailed p-value | B14: =2*(1-_xlfn.NORM.S.DIST(ABS(B13),TRUE())) -> 2.7045032e-06
A15: Decision | B15: =IF(B14<B4,"Significant increase — real guardrail risk","Not statistically significant") -> Significant increase — real guardrail risk
A17: GUARDRAIL 2: DAYS TO CONVERT (Welch's two-sample t-test)
A18: Significance level (alpha) | B18: 0.05
A19: n — Control (converted users) | B19: =COUNT(Raw_Data!$R$2:$R$1401) -> 22
A20: n — Treatment (converted users) | B20: =COUNT(Raw_Data!$S$2:$S$1401) -> 50
A21: Mean — Control days to convert | B21: =AVERAGE(Raw_Data!$R$2:$R$1401) -> 8.8636364
A22: Mean — Treatment days to convert | B22: =AVERAGE(Raw_Data!$S$2:$S$1401) -> 6.4
A23: Std dev — Control | B23: =_xlfn.STDEV.S(Raw_Data!$R$2:$R$1401) -> 3.6160417
A24: Std dev — Treatment | B24: =_xlfn.STDEV.S(Raw_Data!$S$2:$S$1401) -> 2.9965967
A25: Two-tailed p-value (T.TEST, unequal var.) | B25: =_xlfn.T.TEST(Raw_Data!$R$2:$R$1401,Raw_Data!$S$2:$S$1401,2,3) -> 0.0083285066
A26: Decision | B26: =IF(B25<B18,"Significant — Treatment converts faster","Not statistically significant") -> Significant — Treatment converts faster
A28: GUARDRAIL 3: ENGAGEMENT SCORE (Welch's two-sample t-test)
A29: Significance level (alpha) | B29: 0.05
A30: n — Control (non-missing) | B30: =COUNT(Raw_Data!$T$2:$T$1401) -> 684
A31: n — Treatment (non-missing) | B31: =COUNT(Raw_Data!$U$2:$U$1401) -> 702
A32: Mean — Control engagement | B32: =AVERAGE(Raw_Data!$T$2:$T$1401) -> 57.029532
A33: Mean — Treatment engagement | B33: =AVERAGE(Raw_Data!$U$2:$U$1401) -> 62.940028
A34: Two-tailed p-value (T.TEST, unequal var.) | B34: =_xlfn.T.TEST(Raw_Data!$T$2:$T$1401,Raw_Data!$U$2:$U$1401,2,3) -> 4.5463658e-15
A35: Decision | B35: =IF(B34<B29,"Significant — Treatment more engaged","Not statistically significant") -> Significant — Treatment more engaged
A37: GUARDRAIL 4: REFUND RATE (descriptive only — see note)
A38: Control refunds / users | B38: =SUMIFS(Raw_Data!$N$2:$N$1401,Raw_Data!$C$2:$C$1401,"Control")&" / "&COUNTIF(Raw_Data!$C$2:$C$1401,"Control") -> 0 / 690
A39: Treatment refunds / users | B39: =SUMIFS(Raw_Data!$N$2:$N$1401,Raw_Data!$C$2:$C$1401,"Treatment")&" / "&COUNTIF(Raw_Data!$C$2:$C$1401,"Treatment") -> 3 / 710
A40: Note: a formal z-test is not run here — with zero refund events in Control, the pooled-proportion z-test is unreliable (near-zero expected cell counts). Treat this as a metric to keep monitoring as volume grows, not a tested guardrail.
